<mujoco model="blue_full">

    <compiler angle="radian" />
    <option timestep="0.01" gravity="0 0 0" />
    <size njmax="500" nconmax="100" />

    <default>
        <joint armature="0.04" damping="1" limited="true" />
        <geom friction=".5 .1 .1" margin="0.002" condim="1" contype="0" conaffinity="0" />
    </default>

    <asset>
        <mesh name="robot_base_link" file="./meshes/robot_base_link.STL" />
        <mesh name="arm_base_link_v1" file="./meshes/arm_base_link_v1.STL" />
        <mesh name="roll_link_v1" file="./meshes/roll_link_v1.STL" />
        <mesh name="lift_link_v1" file="./meshes/lift_link_v1.STL" />
        <mesh name="hand_base_link" file="./meshes/hand_base_link.STL" />
        <mesh name="finger_limb_link" file="./meshes/finger_limb_link.STL" />
        <mesh name="finger_tip_link" file="./meshes/finger_tip_link.STL" />
        <mesh name="camera_link" file="./meshes/camera_link.STL" />

        <texture name="skybox" type="skybox" builtin="gradient" rgb1=".4 .6 .8" rgb2="0 0 0" width="1024" height="1024" mark="random" markrgb="1 1 1"/>
        <texture name="texplane" type="2d" builtin="checker" rgb1="0.5961 0.5647 0.4784" rgb2="0.3843 0.32941 0.19215" width="512" height="512" mark="cross" markrgb=".8 .8 .8"/>
        <material name="matplane" reflectance="0.3" texture="texplane" texrepeat="1 1" texuniform="true"/>
    </asset>

    <worldbody>
        <light directional="true" diffuse=".8 .8 .8" specular="0.1 0.1 0.1" pos="0 0 2.5" dir="0 0 -1" castshadow="false"/>
        <geom name="ground" type="plane" size="6 6 1" pos="0 0 -1." quat="1 0 0 0" material="matplane" condim="1"/>
        <body name="base_link" pos="0 0 0">
            <inertial pos="-0.0340721 -5.82248e-06 -0.701353" quat="0.999916 3.15548e-05 -0.0129229 -1.90294e-05" mass="16.2842" diaginertia="2.15017 1.86083 0.792594" />
            <geom type="mesh" rgba="0.2784 0.2784 0.2784 1" mesh="robot_base_link" />
            <body name="left_base_link" pos="-0.01409 0.11289 0" quat="-0.0778325 0.246839 0.290463 0.921219">
                <inertial pos="0.0560024 0.000189446 0.0201836" quat="-0.000530006 0.707989 0.00204572 0.70622" mass="0.284612" diaginertia="0.00239707 0.00197713 0.000716923" />
                <geom type="mesh" rgba="0.792157 0.819608 0.933333 1" mesh="arm_base_link_v1" />
                <body name="left_shoulder_roll_link" pos="0 0 0.087371" quat="-3.67321e-06 1 0 0">
                    <inertial pos="0.00526386 2.70692e-05 -0.0641638" quat="0.999876 0.0133095 -0.00835638 -0.000644765" mass="1.88492" diaginertia="0.00615005 0.00509851 0.00418291" />
                    <!--joint name="left_base_roll_joint" pos="0 0 0" axis="0 0 1" limited="true" range="-2.3412 3.3999" /-->
                    <geom type="mesh" rgba="1 1 1 1" mesh="roll_link_v1" />
                    <body name="left_shoulder_lift_link" pos="-0.01143 0 -0.18056" quat="-2.59734e-06 2.59735e-06 -0.707108 0.707105">
                        <inertial pos="-5.00836e-06 0.000232928 -1.77451e-05" mass="0.58967" diaginertia="0.00116314 0.000985221 0.000891661" />
                        <!--joint name="left_shoulder_lift_joint" pos="0 0 0" axis="0 0 1" limited="true" range="-2.2944 0" /-->
                        <geom type="mesh" rgba="0.116747 0.862745 1 1" mesh="lift_link_v1" />
                        <body name="left_elbow_roll_link" pos="0 0.070147 -6.25e-05" quat="0.499124 0.499126 0.500872 -0.500874">
                            <inertial pos="0.00526386 2.70692e-05 -0.0641638" quat="0.999876 0.0133095 -0.00835638 -0.000644765" mass="1.88492" diaginertia="0.00615005 0.00509851 0.00418291" />
                            <!--joint name="left_shoulder_roll_joint" pos="0 0 0" axis="0 0 1" limited="true" range="-2.6761 2.6761" /-->
                            <geom type="mesh" rgba="1 1 1 1" mesh="roll_link_v1" />
                            <body name="left_elbow_lift_link" pos="-0.01143 0 -0.18056" quat="-2.59734e-06 2.59735e-06 -0.707108 0.707105">
                                <inertial pos="-5.00836e-06 0.000232928 -1.77451e-05" mass="0.58967" diaginertia="0.00116314 0.000985221 0.000891661" />
                                <!--joint name="left_elbow_lift_joint" pos="0 0 0" axis="0 0 1" limited="true" range="-2.2944 0" /-->
                                <geom type="mesh" rgba="0.116747 0.862745 1 1" mesh="lift_link_v1" />
                                <body name="left_wrist_roll_link" pos="0 0.070147 -6.25e-05" quat="-0.499128 -0.499122 0.500876 -0.500871">
                                    <inertial pos="0.00526386 2.70692e-05 -0.0641638" quat="0.999876 0.0133095 -0.00835638 -0.000644765" mass="1.6251" diaginertia="0.00615005 0.00509851 0.00418291" />
                                    <!--joint name="left_elbow_roll_joint" pos="0 0 0" axis="0 0 1" limited="true" range="-2.6761 2.6761" /-->
                                    <geom type="mesh" rgba="1 1 1 1" mesh="roll_link_v1" />
                                    <body name="left_wrist_lift_link" pos="-0.01143 0 -0.18056" quat="-2.59734e-06 2.59735e-06 -0.707108 0.707105">
                                        <inertial pos="-5.00836e-06 0.000232928 -1.77451e-05" mass="0.44906" diaginertia="0.00116314 0.000985221 0.000891661" />
                                        <!--joint name="left_wrist_lift_joint" pos="0 0 0" axis="0 0 1" limited="true" range="-2.2944 0" /-->
                                        <geom type="mesh" rgba="0.116747 0.862745 1 1" mesh="lift_link_v1" />
                                        <body name="left_end_roll_link" pos="0 0.070147 -6.25e-05" quat="-2.59734e-06 2.59735e-06 0.707108 -0.707105">
                                            <inertial pos="0.00526386 2.70692e-05 -0.0641638" quat="0.99991 0.000246685 0.0133803 0.00035395" mass="0.65711" diaginertia="0.00578835 0.00530224 0.0034223" />
                                            <!--joint name="left_wrist_roll_joint" pos="0 0 0" axis="0 0 1" limited="true" range="-2.6761 2.6761" /-->
                                            <geom type="mesh" rgba="1 1 1 1" mesh="hand_base_link" />
                                            <body name="left_gripper_link" pos="0 0 -0.1" quat="0.535369 0.498747 0.498747 -0.464631">
                                                <inertial pos="-7.00549e-05 2.51272e-05 -0.0523671" quat="1 5.54202e-05 -0.000544908 -0.000762021" mass="0.00471098" diaginertia="0.000916889 0.000877269 0.000293332" />
                                                <!--<joint name="left_gripper_joint" pos="0 0 0" axis="0 0 1" limited="true" range="0 1.05" />-->
                                            </body>
                                            <body name="left_r_finger_link" pos="0 0.030703 -0.071979" quat="0.631851 -0.317432 -0.631853 0.317432">
                                                <inertial pos="0.000467332 0.0122666 1.16453e-07" quat="0.705809 0.705807 -0.042877 -0.0427953" mass="0.0384621" diaginertia="1.95846e-05 1.92561e-05 5.02091e-06" />
                                                <!--<joint name="left_r_finger_joint" pos="0 0 0" axis="0 0 1" />-->
                                                <geom type="mesh" rgba="0.792157 0.819608 0.933333 1" mesh="finger_limb_link" />
                                                <body name="left_r_finger_tip_link" pos="0 0.06 0" quat="0.222329 0.222329 -0.671246 -0.671244">
                                                    <inertial pos="0.000428096 -6.39629e-08 0.016281" quat="0.982245 -0.000139751 0.187603 -0.000716219" mass="0.00964245" diaginertia="1.96342e-06 1.95368e-06 4.76554e-07" />
                                                    <!--<joint name="left_r_finger_tip_joint" pos="0 0 0" axis="0 1 0" />-->
                                                    <geom type="mesh" rgba="0.792157 0.819608 0.933333 1" mesh="finger_tip_link" />
                                                </body>
                                            </body>
                                            <body name="left_l_finger_link" pos="0 -0.030703 -0.071979" quat="0.31743 -0.631852 0.317435 -0.631852">
                                                <inertial pos="0.000467332 0.0122666 1.16453e-07" quat="0.705809 0.705807 -0.042877 -0.0427953" mass="0.0384621" diaginertia="1.95846e-05 1.92561e-05 5.02091e-06" />
                                                <!--<joint name="left_l_finger_joint" pos="0 0 0" axis="0 0 1" />-->
                                                <geom type="mesh" rgba="0.792157 0.819608 0.933333 1" mesh="finger_limb_link" />
                                                <body name="left_l_finger_tip_link" pos="0 0.06 0" quat="0.222329 0.222329 -0.671246 -0.671244">
                                                    <inertial pos="0.000428096 -6.39629e-08 0.016281" quat="0.982245 -0.000139751 0.187603 -0.000716219" mass="0.00964245" diaginertia="1.96342e-06 1.95368e-06 4.76554e-07" />
                                                    <!--<joint name="left_l_finger_tip_joint" pos="0 0 0" axis="0 1 0" />-->
                                                    <geom type="mesh" rgba="0.792157 0.819608 0.933333 1" mesh="finger_tip_link" />
                                                </body>
                                            </body>
                                            <body name="left_gripper_finger_link" pos="0 0 -0.18" quat="0.707107 -1.29867e-06 0.707107 -1.29867e-06">
                                                <inertial pos="0 0 -0.18" quat="0.707107 -1.29867e-06 0.707107 -1.29867e-06" mass="0" diaginertia="0 0 0" />
                                            </body>
                                        </body>
                                    </body>
                                    <body name="left_wrist_accel_link" pos="-0.0200083 -0.00051 -0.111067" quat="0.69759 0.69759 0.115618 -0.115618">
                                        <inertial pos="-0.0200083 -0.00051 -0.111067" quat="0.69759 0.69759 0.115618 -0.115618" mass="0" diaginertia="0 0 0" />
                                    </body>
                                </body>
                            </body>
                            <body name="left_elbow_accel_link" pos="-0.0200083 -0.00051 -0.111067" quat="0.69759 0.69759 0.115618 -0.115618">
                                <inertial pos="-0.0200083 -0.00051 -0.111067" quat="0.69759 0.69759 0.115618 -0.115618" mass="0" diaginertia="0 0 0" />
                            </body>
                        </body>
                    </body>
                    <body name="left_shoulder_accel_link" pos="-0.0200083 -0.00051 -0.111067" quat="0.69759 0.69759 0.115618 -0.115618">
                        <inertial pos="-0.0200083 -0.00051 -0.111067" quat="0.69759 0.69759 0.115618 -0.115618" mass="0" diaginertia="0 0 0" />
                    </body>
                </body>
            </body>

            <body name="right_base_link" pos="-0.01409 -0.11289 0" quat="0.0778258 0.246842 -0.290461 0.921219">
                <inertial pos="0.0560024 0.000189446 0.0201836" quat="-0.000530006 0.707989 0.00204572 0.70622" mass="0.284612" diaginertia="0.00239707 0.00197713 0.000716923" />
                <geom type="mesh" rgba="0.792157 0.819608 0.933333 1" mesh="arm_base_link_v1" />
                <body name="right_shoulder_roll_link" pos="0 0 0.087371" quat="-3.67321e-06 1 0 0">
                    <inertial pos="0.00526386 2.70692e-05 -0.0641638" quat="0.999876 0.0133095 -0.00835638 -0.000644765" mass="1.88492" diaginertia="0.00615005 0.00509851 0.00418291" />
                    <joint name="right_base_roll_joint" pos="0 0 0" axis="0 0 1" limited="true" range="-3.3999 2.3412" />
                    <geom type="mesh" rgba="1 1 1 1" mesh="roll_link_v1" />
                    <body name="right_shoulder_lift_link" pos="-0.01143 0 -0.18056" quat="-2.59734e-06 2.59735e-06 -0.707108 0.707105">
                        <inertial pos="-5.00836e-06 0.000232928 -1.77451e-05" mass="0.58967" diaginertia="0.00116314 0.000985221 0.000891661" />
                        <joint name="right_shoulder_lift_joint" pos="0 0 0" axis="0 0 1" limited="true" range="-2.2944 0" />
                        <geom type="mesh" rgba="0.116747 0.862745 1 1" mesh="lift_link_v1" />
                        <body name="right_elbow_roll_link" pos="0 0.070147 -6.25e-05" quat="-0.499128 -0.499122 0.500876 -0.500871">
                            <inertial pos="0.00526386 2.70692e-05 -0.0641638" quat="0.999876 0.0133095 -0.00835638 -0.000644765" mass="1.88492" diaginertia="0.00615005 0.00509851 0.00418291" />
                            <joint name="right_shoulder_roll_joint" pos="0 0 0" axis="0 0 1" limited="true" range="-2.6761 2.6761" />
                            <geom type="mesh" rgba="1 1 1 1" mesh="roll_link_v1" />
                            <body name="right_elbow_lift_link" pos="-0.01143 0 -0.18056" quat="-2.59734e-06 2.59735e-06 -0.707108 0.707105">
                                <inertial pos="-5.00836e-06 0.000232928 -1.77451e-05" mass="0.58967" diaginertia="0.00116314 0.000985221 0.000891661" />
                                <joint name="right_elbow_lift_joint" pos="0 0 0" axis="0 0 1" limited="true" range="-2.2944 0" />
                                <geom type="mesh" rgba="0.116747 0.862745 1 1" mesh="lift_link_v1" />
                                <body name="right_wrist_roll_link" pos="0 0.070147 -6.25e-05" quat="0.499124 0.499126 0.500872 -0.500874">
                                    <inertial pos="0.00526386 2.70692e-05 -0.0641638" quat="0.999876 0.0133095 -0.00835638 -0.000644765" mass="1.6251" diaginertia="0.00615005 0.00509851 0.00418291" />
                                    <joint name="right_elbow_roll_joint" pos="0 0 0" axis="0 0 1" limited="true" range="-2.6761 2.6761" />
                                    <geom type="mesh" rgba="1 1 1 1" mesh="roll_link_v1" />
                                    <body name="right_wrist_lift_link" pos="-0.01143 0 -0.18056" quat="-2.59734e-06 2.59735e-06 -0.707108 0.707105">
                                        <inertial pos="-5.00836e-06 0.000232928 -1.77451e-05" mass="0.44906" diaginertia="0.00116314 0.000985221 0.000891661" />
                                        <joint name="right_wrist_lift_joint" pos="0 0 0" axis="0 0 1" limited="true" range="-2.2944 0" />
                                        <geom type="mesh" rgba="0.116747 0.862745 1 1" mesh="lift_link_v1" />
                                        <body name="right_end_roll_link" pos="0 0.070147 -6.25e-05" quat="-2.59734e-06 2.59735e-06 0.707108 -0.707105">
                                            <inertial pos="0.00526386 2.70692e-05 -0.0641638" quat="0.99991 0.000246685 0.0133803 0.00035395" mass="0.65711" diaginertia="0.00578835 0.00530224 0.0034223" />
                                            <joint name="right_wrist_roll_joint" pos="0 0 0" axis="0 0 1" limited="true" range="-2.6761 2.6761" />
                                            <geom type="mesh" rgba="1 1 1 1" mesh="hand_base_link" />
                                            <body name="right_gripper_link" pos="0 0 -0.1" quat="0.535369 0.498747 0.498747 -0.464631">
                                                <inertial pos="-7.00549e-05 2.51272e-05 -0.0523671" quat="1 5.54202e-05 -0.000544908 -0.000762021" mass="0.00471098" diaginertia="0.000916889 0.000877269 0.000293332" />
                                                <!--<joint name="right_gripper_joint" pos="0 0 0" axis="0 0 1" limited="true" range="0 1.05" />-->
                                                <body name="peg-top" pos="0 0.1 0">
                                                    <geom type="cylinder" rgba="1.0 0.0 0.0 1" pos="0 -0.15 0" size="0.02 0.07" quat="0.2 0.2 0 0" contype="1" conaffinity="1"/>
                                                </body>
                                                <body name="peg-center" pos="0 0.1 0">
                                                    <geom type="cylinder" rgba="0.0 1.0 0.0 1" pos="0 0 0" size="0.02 0.07" quat="1.0 1.0 0 0" contype="1" conaffinity="1"/>
                                                </body>
                                                <body name="peg-bottom" pos="0 0.1 0">
                                                    <geom type="cylinder" rgba="0.0 0.0 1.0 1" pos="0 0.15 0" size="0.02 0.07" quat="0.2 0.2 0 0" contype="1" conaffinity="1"/>
                                                </body>
                                            </body>
                                            <body name="right_r_finger_link" pos="0 0.030703 -0.071979" quat="0.631851 -0.317432 -0.631853 0.317432">
                                                <inertial pos="0.000467332 0.0122666 1.16453e-07" quat="0.705809 0.705807 -0.042877 -0.0427953" mass="0.0384621" diaginertia="1.95846e-05 1.92561e-05 5.02091e-06" />
                                                <!--<joint name="right_r_finger_joint" pos="0 0 0" axis="0 0 1" />-->
                                                <geom type="mesh" rgba="0.792157 0.819608 0.933333 1" mesh="finger_limb_link" />
                                                <body name="right_r_finger_tip_link" pos="0 0.06 0" quat="0.222329 0.222329 -0.671246 -0.671244">
                                                    <inertial pos="0.000428096 -6.39629e-08 0.016281" quat="0.982245 -0.000139751 0.187603 -0.000716219" mass="0.00964245" diaginertia="1.96342e-06 1.95368e-06 4.76554e-07" />
                                                    <!--<joint name="right_r_finger_tip_joint" pos="0 0 0" axis="0 1 0" />-->
                                                    <geom type="mesh" rgba="0.792157 0.819608 0.933333 1" mesh="finger_tip_link" />
                                                </body>
                                            </body>
                                            <body name="right_l_finger_link" pos="0 -0.030703 -0.071979" quat="0.31743 -0.631852 0.317435 -0.631852">
                                                <inertial pos="0.000467332 0.0122666 1.16453e-07" quat="0.705809 0.705807 -0.042877 -0.0427953" mass="0.0384621" diaginertia="1.95846e-05 1.92561e-05 5.02091e-06" />
                                                <!--<joint name="right_l_finger_joint" pos="0 0 0" axis="0 0 1" />-->
                                                <geom type="mesh" rgba="0.792157 0.819608 0.933333 1" mesh="finger_limb_link" />
                                                <body name="right_l_finger_tip_link" pos="0 0.06 0" quat="0.222329 0.222329 -0.671246 -0.671244">
                                                    <inertial pos="0.000428096 -6.39629e-08 0.016281" quat="0.982245 -0.000139751 0.187603 -0.000716219" mass="0.00964245" diaginertia="1.96342e-06 1.95368e-06 4.76554e-07" />
                                                    <!--<joint name="right_l_finger_tip_joint" pos="0 0 0" axis="0 1 0" />-->
                                                    <geom type="mesh" rgba="0.792157 0.819608 0.933333 1" mesh="finger_tip_link" />
                                                </body>
                                            </body>
                                            <body name="right_gripper_finger_link" pos="0 0 -0.18" quat="0.707107 -1.29867e-06 0.707107 -1.29867e-06">
                                                <inertial pos="0 0 -0.18" quat="0.707107 -1.29867e-06 0.707107 -1.29867e-06" mass="0" diaginertia="0 0 0" />
                                            </body>
                                        </body>
                                    </body>
                                    <body name="right_wrist_accel_link" pos="-0.0200083 -0.00051 -0.111067" quat="0.69759 0.69759 0.115618 -0.115618">
                                        <inertial pos="-0.0200083 -0.00051 -0.111067" quat="0.69759 0.69759 0.115618 -0.115618" mass="0" diaginertia="0 0 0" />
                                    </body>
                                </body>
                            </body>
                            <body name="right_elbow_accel_link" pos="-0.0200083 -0.00051 -0.111067" quat="0.69759 0.69759 0.115618 -0.115618">
                                <inertial pos="-0.0200083 -0.00051 -0.111067" quat="0.69759 0.69759 0.115618 -0.115618" mass="0" diaginertia="0 0 0" />
                            </body>
                        </body>
                    </body>
                    <body name="right_shoulder_accel_link" pos="-0.0200083 -0.00051 -0.111067" quat="0.69759 0.69759 0.115618 -0.115618">
                        <inertial pos="-0.0200083 -0.00051 -0.111067" quat="0.69759 0.69759 0.115618 -0.115618" mass="0" diaginertia="0 0 0" />
                    </body>
                </body>
            </body>

            <body name="camera_link" pos="-0.01905 0 0.303507" quat="0.707107 0.707107 0 0">
                <inertial pos="-0.00759217 0.0650724 0.000615586" quat="0.999769 -0.000313494 0.000866284 -0.0214595" mass="0.274759" diaginertia="0.000597521 0.000569066 0.000184847" />
                <geom type="mesh" rgba="0.792157 0.819608 0.933333 1" mesh="camera_link" />
                <body name="camera_view_link" pos="0.01905 0.072775 0" quat="0.707107 0 -0.707107 0">
                    <inertial pos="0.01905 0.072775 0" quat="0.707107 0 -0.707107 0" mass="0" diaginertia="0 0 0" />
                </body>
            </body>
        </body>

        <body name="goal_peg" pos="0.05 -0.8 0.2">
            <body name="g1" pos="0.0 0.3 -0.4">
                <geom name="g1" type="sphere" rgba="1.0 0.0 0.0 1" pos="0.0 0.0 0.0" size="0.01" />
            </body>
            <body name="g2" pos="0.0 0.3 -0.55">
                <geom name="g2" type="sphere" rgba="0.0 1.0 0.0 1" pos="0.0 0.0 0.0" size="0.01" />
            </body>
            <body name="g3" pos="0.0 0.3 -0.7">
                <geom name="g3" type="sphere" rgba="0.0 0.0 1.0 1" pos="0.0 0.0 0.0" size="0.01" />
            </body>

            <body name="w1" pos="0.216 0.3 -0.55">
                <geom name="w1" rgba="0.2 0.2 0.8 1" type="box" size="0.183 0.469 0.025" contype="1" conaffinity="1" />
            </body>

            <body name="w2" pos="-0.216 0.3 -0.55">
                <geom name="w2" rgba="0.2 0.2 0.8 1" type="box" size="0.183 0.469 0.025" contype="1" conaffinity="1" />
            </body>

            <body name="w3" pos="0.0 0.55 -0.55">
                <geom name="w3" rgba="0.2 0.2 0.8 1" type="box" size="0.04 0.22 0.025" contype="1" conaffinity="1" />
            </body>

            <body name="w4" pos="0.0 0.05 -0.55">
                <geom name="w4" rgba="0.2 0.2 0.8 1" type="box" size="0.04 0.22 0.025" contype="1" conaffinity="1" />
            </body>
        </body>
    </worldbody>

    <actuator>
        <motor ctrlrange="-20.0 20.0" gear="1.0" joint="right_base_roll_joint" />
        <motor ctrlrange="-20.0 20.0" gear="1.0" joint="right_shoulder_lift_joint" />
        <motor ctrlrange="-20.0 20.0" gear="1.0" joint="right_shoulder_roll_joint" />
        <motor ctrlrange="-20.0 20.0" gear="1.0" joint="right_elbow_lift_joint" />
        <motor ctrlrange="-20.0 20.0" gear="1.0" joint="right_elbow_roll_joint" />
        <motor ctrlrange="-10.0 10.0" gear="1.0" joint="right_wrist_lift_joint" />
        <motor ctrlrange="-10.0 10.0" gear="1.0" joint="right_wrist_roll_joint" />

        <!--<motor ctrllimited="true" ctrlrange="-2.0 2.0" joint="robotfinger_actuator_joint" />
        <position ctrllimited="true" kp="5.0" ctrlrange="0 1.4" joint="right_fingerlimb_joint" />
        <position ctrllimited="true" kp="5.0" ctrlrange="-1.4 0" joint="right_fingertip_joint" />
        <position ctrllimited="true" kp="5.0" ctrlrange="0 1.4" joint="left_fingerlimb_joint" />
        <position ctrllimited="true" kp="5.0" ctrlrange="-1.4 0" joint="left_fingertip_joint" />-->

        <!--<motor ctrlrange="-20.0 20.0" gear="1.0" joint="left_base_roll_joint" />
        <motor ctrlrange="-20.0 20.0" gear="1.0" joint="left_shoulder_lift_joint" />
        <motor ctrlrange="-20.0 20.0" gear="1.0" joint="left_shoulder_roll_joint" />
        <motor ctrlrange="-20.0 20.0" gear="1.0" joint="left_elbow_lift_joint" />
        <motor ctrlrange="-20.0 20.0" gear="1.0" joint="left_elbow_roll_joint" />
        <motor ctrlrange="-10.0 10.0" gear="1.0" joint="left_wrist_lift_joint" />
        <motor ctrlrange="-10.0 10.0" gear="1.0" joint="left_wrist_roll_joint" />-->
  </actuator>
</mujoco>
